Workbook

Sheet Inicio
A1: LABORATORIO · CHOQUES MACROECONÓMICOS Y VAN
A2: Macroeconomía 200 FP · Maestría en Formulación y Evaluación de Proyectos
A4: Propósito
A5: Analizar cómo un choque macroeconómico modifica los supuestos de un proyecto y, por esa vía, altera sus flujos de efectivo y su Valor Actual Neto (VAN). El énfasis está en identificar el canal de transmisión: shock → variable del proyecto → flujo → VAN.
A9: Secuencia de trabajo
A10: 1 | B10: Construya el flujo del escenario base. | D10: Convenciones del archivo
A11: 2 | B11: Calcule el VAN base. | D11: Dato / supuesto | E11: Texto azul | F11: Valor entregado por el caso.
A12: 3 | B12: Identifique el tipo de choque y la variable afectada. | D12: Shock | E12: Fondo rosado | F12: Cambio asociado al escenario adverso.
A13: 4 | B13: Aplique el shock únicamente a las variables pertinentes. | D13: Cálculo | E13: Celda blanca | F13: Construya la fórmula en Excel.
A14: 5 | B14: Recalcule el flujo y el VAN bajo shock. | D14: Resultado | E14: Bloque resumen | F14: Use para discutir el impacto sobre el VAN.
A15: 6 | B15: Mida el cambio absoluto y porcentual del VAN.
A16: 7 | B16: Explique el principal canal de vulnerabilidad del proyecto. | D16: Los datos son ficticios y se utilizan únicamente con fines académicos. No se incorporan impuestos, depreciaciones, capital de trabajo detallado ni estructura de deuda. Trabaje con un horizonte de 5 años y utilice el valor residual indicado en cada caso.
A20: GRUPO E INTEGRANTES
A21: Carnet | B21: Nombre completo
C22: Coordinador (solo el coordinador sube el laboratorio)

Sheet G1 Hotel
A1: GRUPO 1 · PROYECTO HOTELERO
A2: Shock de demanda · ocupación y tarifa
A4: Supuestos del escenario base | E4: Choque macroeconómico
A5: Variable | B5: Dato | E5: Año | F5: Ocupación | G5: Δ tarifa
A6: Habitaciones disponibles | B6: 60 | E6: 1 | F6: 0.5 | G6: -0.08
A7: Ocupación promedio | B7: 0.65 | E7: 2 | F7: 0.5 | G7: -0.08
A8: Tarifa promedio por noche | B8: 650 | E8: 3 | F8: 0.58 | G8: -0.04
A9: Costo variable por habitación ocupada | B9: 170 | E9: 4 | F9: 0.65 | G9: 0
A10: Costos fijos anuales | B10: 2600000 | E10: 5 | F10: 0.65 | G10: 0
A11: Mantenimiento anual | B11: 200000
A12: Inversión inicial | B12: 12000000 | E12: Shock: una desaceleración regional reduce los viajes y el turismo. La ocupación cae y el hotel debe ajustar temporalmente la tarifa.
A13: Valor residual (año 5) | B13: 3000000
A14: Tasa de descuento | B14: 0.1
A16: Escenario base
A17: Concepto | B17: Año 0 | C17: Año 1 | D17: Año 2 | E17: Año 3 | F17: Año 4 | G17: Año 5
A18: Ocupación
A19: Tarifa promedio
A20: Habitaciones ocupadas
A21: Ingresos
A22: Costo variable
A23: Costos fijos
A24: Mantenimiento
A25: Flujo neto
A26: Factor de descuento
A27: Valor presente del flujo
A28: Valor residual
A29: VAN
A31: Escenario bajo shock
A32: Concepto | B32: Año 0 | C32: Año 1 | D32: Año 2 | E32: Año 3 | F32: Año 4 | G32: Año 5
A33: Ocupación
A34: Tarifa promedio
A35: Habitaciones ocupadas
A36: Ingresos
A37: Costo variable
A38: Costos fijos
A39: Mantenimiento
A40: Flujo neto
A41: Factor de descuento
A42: Valor presente del flujo
A43: Valor residual
...

Sheet G2 Agroindustria
A1: GRUPO 2 · PLANTA AGROINDUSTRIAL
A2: Shock adverso de oferta · costos variables
A4: Supuestos del escenario base | E4: Choque macroeconómico
A5: Variable | B5: Dato | E5: Año | F5: Δ costo variable
A6: Unidades vendidas por año | B6: 500000 | E6: 1 | F6: 0.2
A7: Precio por unidad | B7: 42 | E7: 2 | F7: 0.2
A8: Costo variable por unidad | B8: 23 | E8: 3 | F8: 0.2
A9: Costos fijos anuales | B9: 4000000 | E9: 4 | F9: 0.05
A10: Mantenimiento anual | B10: 500000 | E10: 5 | F10: 0
A11: Inversión inicial | B11: 15000000
A12: Valor residual (año 5) | B12: 3000000 | E12: Shock: aumentan combustibles, empaques y transporte. El costo variable unitario sube y la empresa no puede trasladar inicialmente el incremento al precio.
A13: Tasa de descuento | B13: 0.1
A16: Escenario base
A17: Concepto | B17: Año 0 | C17: Año 1 | D17: Año 2 | E17: Año 3 | F17: Año 4 | G17: Año 5
A18: Unidades vendidas
A19: Precio unitario
A20: Costo variable unitario
A21: Ingresos
A22: Costo variable total
A23: Costos fijos
A24: Mantenimiento
A25: Flujo neto
A26: Factor de descuento
A27: Valor presente del flujo
A28: Valor residual
A29: VAN
A31: Escenario bajo shock
A32: Concepto | B32: Año 0 | C32: Año 1 | D32: Año 2 | E32: Año 3 | F32: Año 4 | G32: Año 5
A33: Unidades vendidas
A34: Precio unitario
A35: Costo variable unitario
A36: Ingresos
A37: Costo variable total
A38: Costos fijos
A39: Mantenimiento
A40: Flujo neto
A41: Factor de descuento
A42: Valor presente del flujo
A43: Valor residual
A44: VAN
...

Sheet G3 Consumo
A1: GRUPO 3 · BIENES DE CONSUMO
A2: Shock de demanda · volumen y precio
A4: Supuestos del escenario base | E4: Choque macroeconómico
A5: Variable | B5: Dato | E5: Año | F5: Δ volumen | G5: Δ precio
A6: Unidades vendidas por año | B6: 300000 | E6: 1 | F6: -0.2 | G6: -0.05
A7: Precio unitario | B7: 60 | E7: 2 | F7: -0.15 | G7: -0.05
A8: Costo variable unitario | B8: 32 | E8: 3 | F8: -0.08 | G8: -0.02
A9: Costos fijos anuales | B9: 4500000 | E9: 4 | F9: 0 | G9: 0
A10: Mantenimiento anual | B10: 300000 | E10: 5 | F10: 0 | G10: 0
A11: Inversión inicial | B11: 12000000
A12: Valor residual (año 5) | B12: 2500000 | E12: Shock: se desacelera el ingreso de los hogares. Disminuye el volumen vendido y la empresa realiza descuentos temporales para sostener la demanda.
A13: Tasa de descuento | B13: 0.1
A16: Escenario base
A17: Concepto | B17: Año 0 | C17: Año 1 | D17: Año 2 | E17: Año 3 | F17: Año 4 | G17: Año 5
A18: Unidades vendidas
A19: Precio unitario
A20: Costo variable unitario
A21: Ingresos
A22: Costo variable total
A23: Costos fijos
A24: Mantenimiento
A25: Flujo neto
A26: Factor de descuento
A27: Valor presente del flujo
A28: Valor residual
A29: VAN
A31: Escenario bajo shock
A32: Concepto | B32: Año 0 | C32: Año 1 | D32: Año 2 | E32: Año 3 | F32: Año 4 | G32: Año 5
A33: Unidades vendidas
A34: Precio unitario
A35: Costo variable unitario
A36: Ingresos
A37: Costo variable total
A38: Costos fijos
A39: Mantenimiento
A40: Flujo neto
A41: Factor de descuento
A42: Valor presente del flujo
A43: Valor residual
A44: VAN
...

Sheet G4 Solar
A1: GRUPO 4 · GENERACIÓN SOLAR
A2: Shock financiero · aumento de la tasa de descuento
A4: Supuestos del escenario base | E4: Choque macroeconómico
A5: Variable | B5: Dato | E5: Las condiciones financieras se endurecen. El costo de capital requerido para proyectos de este tipo aumenta de 9.0% a 12.5%. Los flujos operativos esperados no cambian.
A6: Inversión inicial | B6: 20000000
A7: Flujo anual esperado | B7: 5500000
A8: Horizonte | B8: 5
A9: Valor residual (año 5) | B9: 4000000
A10: Tasa de descuento base | B10: 0.09
A11: Tasa de descuento bajo shock | B11: 0.125
A13: Escenario base
A14: Concepto | B14: Año 0 | C14: Año 1 | D14: Año 2 | E14: Año 3 | F14: Año 4 | G14: Año 5
A15: Flujo operativo
A16: Flujo neto
A17: Factor de descuento
A18: Valor presente del flujo
A19: Valor residual
A20: VAN
A23: Escenario bajo shock
A24: Concepto | B24: Año 0 | C24: Año 1 | D24: Año 2 | E24: Año 3 | F24: Año 4 | G24: Año 5
A25: Flujo operativo
A26: Flujo neto
A27: Factor de descuento
A28: Valor presente del flujo
A29: Valor residual
A30: VAN
A33: Resultados para discusión
A34: Indicador | B34: Resultado
A35: VAN base | B35: =B20 -> 0
A36: VAN con tasa 12.5% | B36: =B30 -> 0
A37: Pérdida absoluta de valor | B37: =B36-B35 -> 0
A38: Pérdida porcentual | B38: =IF(B35=0,"",B37/B35)
A40: Conclusión del grupo (máximo 150 palabras): explique por qué el VAN puede disminuir aunque el flujo operativo no cambie e identifique la variable macrofinanciera que debería monitorearse con mayor atención.

Sheet Comparación
A1: COMPARACIÓN DE RESULTADOS
A2: Una misma economía, distintos canales de transmisión hacia el VAN
A4: Matriz comparativa
A5: Proyecto | B5: Shock dominante | C5: Variable afectada | D5: VAN base | E5: VAN shock | F5: Δ VAN | G5: % Δ VAN
A6: Hotel | B6: Demanda | C6: Ocupación / tarifa | D6: ='G1 Hotel'!B48 -> 0 | E6: ='G1 Hotel'!B49 -> 0 | F6: =E6-D6 -> 0 | G6: =IF(D6=0,"",F6/D6)
A7: Agroindustria | B7: Oferta | C7: Costo variable | D7: ='G2 Agroindustria'!B48 -> 0 | E7: ='G2 Agroindustria'!B49 -> 0 | F7: =E7-D7 -> 0 | G7: =IF(D7=0,"",F7/D7)
A8: Bienes de consumo | B8: Demanda | C8: Volumen / precio | D8: ='G3 Consumo'!B48 -> 0 | E8: ='G3 Consumo'!B49 -> 0 | F8: =E8-D8 -> 0 | G8: =IF(D8=0,"",F8/D8)
A9: Generación solar | B9: Financiero | C9: Tasa de descuento | D9: ='G4 Solar'!B35 -> 0 | E9: ='G4 Solar'!B36 -> 0 | F9: =E9-D9 -> 0 | G9: =IF(D9=0,"",F9/D9)
A12: Lectura conjunta
A13: Use esta hoja al final de las exposiciones. Compare no solo qué proyecto pierde más VAN, sino por qué. El objetivo es distinguir si la vulnerabilidad proviene de ventas, ocupación, precios, costos o del costo de capital.
